Workbook

Sheet 📊 Dashboard
A1: RENTTIA · Dashboard Rent to Rent
A2: ="📍 "& 'Calculadora R2R'!B7 &" — "&TEXT(TODAY(),"DD/MM/YYYY")
A4: 📊 RESULTADOS MENSUALES
B5: 💵 Ingresos brutos estimados / mes | E5: 💶 Alquiler neto al propietario / mes
B6: ='Calculadora R2R'!B30 | E6: ='Calculadora R2R'!B8
B9: 🧾 IVA 21% no deducible / mes | E9: 💡 Gastos suministros totales / mes
B10: ='Calculadora R2R'!B32 | E10: ='Calculadora R2R'!B31
A13: 🏆 MARGEN Y GANANCIA
B14: 🏆 MARGEN NETO mensual real | E14: 👤 Ganancia neta por habitación / mes
B15: ='Calculadora R2R'!B37 | E15: ='Calculadora R2R'!B38
A18: 🚪 HABITACIONES Y PRECIOS
B19: 🏠 Total habitaciones (originales + conversión) | E19: 📐 Precio medio por habitación
B20: ='Calculadora R2R'!B11 | E20: ='Calculadora R2R'!B29
A23: 💰 INVERSIÓN INICIAL
B24: 🏗️ Inversión total en obra y mobiliario | E24: 🏦 Fianza al propietario (2 meses)
B25: ='Calculadora R2R'!B26 | E25: ='Calculadora R2R'!B41
B28: 💸 DESEMBOLSO INICIAL TOTAL (inversión + fianza)
B29: ='Calculadora R2R'!B26+'Calculadora R2R'!B41
A31: 📈 RETORNO
B32: 🚀 Payback — meses para recuperar inversión | E32: 📊 ROI anual neto sobre inversión
B33: ='Calculadora R2R'!B42 | E33: ='Calculadora R2R'!B43
B36: 🏆 GANANCIA NETA ANUAL REAL
B37: ='Calculadora R2R'!B37*12
A39: 🎯 VEREDICTO — Regla de la Mentora
B40: =IF(AND('Calculadora R2R'!B38>=100,'Calculadora R2R'!B37>'Calculadora R2R'!B14,IFERROR('Calculadora R2R'!B26/'Calculadora R2R'!B37,99)<=15),"🟢 OPERACIÓN VIABLE — Los 3 filtros en verde","🔴 NO OPERAR — Revisa los filtros en rojo")
B42: 1️⃣ Filtro 1 — Beneficio / hab ≥ 100€ | C42: =IF('Calculadora R2R'!B38>=100,"✅ APTO ("&TEXT('Calculadora R2R'!B38,"#,##0")&" €/hab)","❌ NO APTO ("&TEXT('Calculadora R2R'!B38,"#,##0")&" €/hab)")
B43: 2️⃣ Filtro 2 — Caja resiste vacancia | C43: =IF('Calculadora R2R'!B37>'Calculadora R2R'!B14,"✅ SEGURO (margen "&TEXT('Calculadora R2R'!B37-'Calculadora R2R'!B14,"#,##0")&" € sobre precio máx. hab)","❌ RIESGO (vacancia = pérdidas)")
B44: 3️⃣ Filtro 3 — Payback ≤ 15 meses | C44: =IF(IFERROR('Calculadora R2R'!B26/'Calculadora R2R'!B37,99)<=15,"✅ EXCELENTE (payback "&TEXT(IFERROR('Calculadora R2R'!B26/'Calculadora R2R'!B37,0),"0.0")&" meses)","❌ LENTO (payback "&TEXT(IFERROR('Calculadora R2R'!B26/'Calculadora R2R'!B37,0),"0.0")&" meses)")
A46: RENTTIA · renttia.es · Este dashboard se actualiza automáticamente al cambiar los datos en la hoja "Calculadora R2R"

Sheet Calculadora R2R
A1: RENTTIA · Calculadora Rent to Rent
A2: Regla de la Mentora · IVA 21% integrado · Conversión de salón en habitación
A4: 📋 DATOS DE ENTRADA | E4: ✅ FILTROS — Regla de la Mentora
C5: €/hab | D5: Subtotal | E5: Evaluación automática | G5: Métrica
A7: 🏙️ Ciudad / Zona | B7: Zaragoza Centro
A8: 💶 Alquiler mensual neto al propietario (€) | B8: 900 | E8: =IF(B38>=100,"✅ APTO — Beneficio/hab >= 100€","❌ NO APTO — Beneficio/hab < 100€") | G8: =B38
A9: 🚪 Habitaciones ORIGINALES del piso | B9: 4 | E9: =IF(B37>B14,"✅ SEGURO — Caja > Precio máx. hab","🔴 RIESGO — Vacancia = pérdidas") | G9: =B37-B14
A10: 🔄 Habitaciones EXTRA (conversión salón → 0, 1 o 2 hab.) | B10: 0 | C10: ← cambia: 0, 1 o 2 | E10: =IF(IFERROR(B26/B37,99)<=15,"🚀 EXCELENTE — Payback < 15 meses","⏳ LENTO — Payback > 15 meses") | G10: =IFERROR(B26/B37,0)
A11: 🏠 TOTAL HABITACIONES (originales + conversión) — AUTOMÁTICO | B11: =B9+B10 | C11: = B9 + B10 ✓ automático | E11: VEREDICTO FINAL
A12: 🧱 ¿Las hab. de conversión requieren tabiquería / pladur? | B12: No | C12: ↑ Solo aplica si B10 > 0
A13: 📉 Precio mínimo hab. en la zona (€/mes) | B13: 380 | E13: =IF(AND(B38>=100,B37>B14,IFERROR(B26/B37,99)<=15),"🟢 OPERACIÓN VIABLE — Los 3 filtros en verde","🔴 NO OPERAR — Revisa los filtros en rojo")
A14: 📈 Precio máximo hab. en la zona (€/mes) | B14: 450
A15: 💡 Gastos suministros por habitación (€/mes) | B15: 35
A17: 🏗️ COMPONENTES DE INVERSIÓN — Selecciona lo que necesita el piso
A18: 🎨 ¿Necesita pintura / saneamiento? | B18: No | C18: 200 | D18: =IF(B18="Sí",B11*200,0)
A19: 🪑 ¿Necesita mobiliario completo? | B19: Sí | C19: 650 | D19: =IF(B19="Sí",B11*650,0)
A20: 🍽️ ¿Necesita menaje cocina y zonas comunes? | B20: Sí | C20: 50 | D20: =IF(B20="Sí",B11*50,0)
A21: 🔒 ¿Necesita cerrojos individuales? | B21: Sí | C21: 80 | D21: =IF(B21="Sí",B11*80,0)
A22: 🔦 ¿Necesita iluminación LED? | B22: No | C22: 75 | D22: =IF(B22="Sí",B11*75,0)
A23: 🔨 ¿Necesita reforma estructural? | B23: No | C23: 850 | D23: =IF(B23="Sí",B11*850,0)
A24: 🧱 ¿Tabiquería/pladur para hab. de conversión? (depende de B12) | B24: ← ver B12 | C24: 1200 | D24: =IF(AND(B12="Sí",B10>0),B10*1200,0)
A25: 📸 Fotografía profesional + home staging (siempre incluida) | C25: 75 | D25: =B11*75
A26: 💰 INVERSIÓN TOTAL ESTIMADA (suma de todos los componentes marcados) | B26: =SUM(D18:D25) | C26: ← Cambia Sí/No en col. B
A28: 📊 ANÁLISIS FINANCIERO MENSUAL
A29: 📐 Precio medio por hab. (€/mes) | B29: =(B13+B14)/2
A30: 💵 Ingresos brutos estimados totales (€/mes) | B30: =B29*B11
A31: 💡 Gastos suministros totales (€/mes) | B31: =B15*B11
A32: 🧾 IVA 21% no deducible — gasto real mensual | B32: =B8*0.21
A33: 📋 Retención IRPF Mod.115 a ingresar (19%) | B33: =B8*0.19
A34: 💸 Coste real mensual del alquiler con IVA | B34: =B8+(B8*0.21)
A37: 🏆 MARGEN NETO MENSUAL REAL (tras IVA 21% + suministros) | B37: =B30-B8-(B8*0.21)-B31
A38: 👤 Beneficio neto real por habitación (€/mes) | B38: =B37/B11
A40: 📈 INVERSIÓN Y RETORNO
A41: 🏦 Fianza al propietario (2 meses) | B41: =B8*2
A42: 📅 Payback — Meses para recuperar inversión | B42: =IFERROR(B26/B37,0)
A43: 📊 ROI anual sobre inversión inicial (%) | B43: =IFERROR((B37*12/B26)*100,0)
A44: 💹 Ingresos brutos anuales estimados (€) | B44: =B30*12
A45: 🏦 Beneficio neto anual real (€) | B45: =B37*12
A47: 🧾 RECUERDA — Impacto del IVA 21% en tu margen real
A48: ⚠️ El propietario te factura CON IVA 21% porque eres empresa (arrendamiento uso distinto de vivienda). Tú NO puedes repercutirlo a tus inquilinos (subarriendo residencial exento). Ese 21% es un GASTO DIRECTO que ya está descontado en el Margen Neto (B37). Ejemplo: alquiler 900€ → pagas realmente 900 + 189€ = 1.089€/mes al propietario.
...
