Workbook

Sheet Calculadora R2R
A1: RENTTIA · Calculadora Rent to Rent v2
A2: Regla de la Mentora · IVA integrado por tipo de contrato · Precios individuales por habitación
A4: CONCEPTO | B4: VALOR / SELECCIÓN | C4: € unitario | D4: SUBTOTAL | E4: EVALUACIÓN AUTOMÁTICA | G4: MÉTRICA
A5: 📋 DATOS GENERALES
A6: 🏙️ Ciudad / Zona | B6: Zaragoza
A7: 📄 Tipo de contrato | B7: Explotación (subarriendo propio) | C7: Ver notas fiscales | E7: =IF(B7="Explotación (subarriendo propio)","Renttia arrienda en nombre propio y subarrienda. Propietario factura IVA 21%. Renttia retiene IRPF 19% (Mod.115).",IF(B7="Gestión — Alquiler garantizado","Renttia gestiona en nombre del propietario. Garantiza renta fija al propietario. Sin IVA sobre alquiler. Renttia cobra la diferencia.","Renttia gestiona en nombre del propietario. Cobra "&B8&"% de comisión + IVA 21%. Sin IVA sobre alquiler al propietario."))
A8: % Comisión de gestión (solo «Gestión — A porcentaje») | B8: 25 | C8: % ingreso bruto | E8: =IF(B7="Gestión — A porcentaje","Renttia factura al propietario: "&B8&"% × ingresos + 21% IVA. IVA neutro para Renttia.","— Solo aplica en «Gestión — A porcentaje» —")
A9: 💶 Renta mensual al propietario / renta garantizada (€) | B9: 825 | E9: =IF(B7="Explotación (subarriendo propio)","Coste real = "&TEXT(B9*1.21,"#,##0")&" €/mes (renta + IVA 21% no recuperable). Retención IRPF "&TEXT(B9*0.19,"#,##0")&" €/mes.",IF(B7="Gestión — Alquiler garantizado","Renttia garantiza "&TEXT(B9,"#,##0")&" €/mes al propietario. SIN IVA (arrendamiento residencial exento). Renttia ingresa el exceso.","Propietario recibe "&TEXT(100-B8,"0")&"% de ingresos. Renttia factura "&B8&"% + IVA 21% (neutro para Renttia).")) | G9: =IF(B7="Explotación (subarriendo propio)",B9*1.21,B9)
A10: 🚪 Habitaciones ORIGINALES del piso | B10: 3
A11: 🔄 Habitaciones EXTRA (salón → hab) [0,1,2] | B11: 1 | C11: 0, 1 o 2
A12: 🏠 TOTAL HABITACIONES (automático) | B12: =B10+B11 | C12: =B10 + B11
A13: 🧱 ¿Las hab. de conversión requieren tabiquería/pladur? | B13: Sí | C13: Solo si B11 > 0
A14: 💡 Gastos suministros por habitación (€/mes) | B14: 40 | C14: estimación media
A16: 🏷️ PRECIOS INDIVIDUALES POR HABITACIÓN — Ajusta cada uno según tamaño y calidad
A17: ✏️ Rellena el precio de cada habitación activa. Deja en 0 las que no uses. El total suma todas las celdas — es tan sencillo como eso.
A18: 🛏️ Habitación original 1 ← rellena según B10 | B18: 420 | C18: €/mes
A19: 🛏️ Habitación original 2 | B19: 400 | C19: €/mes
A20: 🛏️ Habitación original 3 | B20: 400 | C20: €/mes
A21: 🛏️ Habitación original 4 (pon 0 si solo tienes 3) | B21: 0 | C21: €/mes
A22: 🛏️ Habitación original 5 (pon 0 si no aplica) | B22: 0 | C22: €/mes
A23: 🛏️ Habitación original 6 (pon 0 si no aplica) | B23: 0 | C23: €/mes
A24: 🔄 Conversión 1 — salón → hab. ← activa si B11 ≥ 1 | B24: 350 | C24: €/mes
A25: 🔄 Conversión 2 — salón → hab. extra ← activa si B11 = 2 | B25: 0 | C25: €/mes
A26: 💵 INGRESOS BRUTOS TOTALES / MES (suma de B18:B25 — pon 0 en las hab. que no uses) | D26: =SUM(B18:B25)
A28: 🏗️ COMPONENTES DE INVERSIÓN — Selecciona lo que necesita el piso
A29: 📐 Metros cuadrados del piso (m²) | B29: 70 | C29: Para reforma integral
A30: 🚿 Número de baños | B30: 1 | C30: Para reforma baño
A31: 🎨 ¿Pintura y saneamiento general? | B31: No | C31: 250 | D31: =IF(B31="Sí",B12*250,0)
A32: 🪑 ¿Mobiliario completo por habitación? | B32: No | C32: 700 | D32: =IF(B32="Sí",B12*700,0)
A33: 🍽️ ¿Menaje cocina y zonas comunes? | B33: No | C33: 300 | D33: =IF(B33="Sí",300,0)
A34: 🔒 ¿Cerrojos individuales? | B34: No | C34: 100 | D34: =IF(B34="Sí",B12*100,0)
A35: 🔦 ¿Iluminación LED? | B35: No | C35: 75 | D35: =IF(B35="Sí",B12*75,0)
A36: 🍳 ¿Reforma de cocina? (precio orientativo) | B36: No | C36: 6000 | D36: =IF(B36="Sí",6000,0)
A37: 🚿 ¿Reforma de baño/s? (precio × nº baños) | B37: No | C37: 4500 | D37: =IF(B37="Sí",B30*4500,0)
A38: 🔨 ¿Reforma integral del piso? (€500/m²) | B38: No | C38: 500 | D38: =IF(B38="Sí",B29*500,0)
A39: 🧱 ¿Tabiquería/pladur hab. de conversión? | B39: ← automático (ver B13) | C39: 1500 | D39: =IF(AND(B13="Sí",B11>0),B11*1500,0)
A40: 📸 Fotografía profesional + home staging (siempre) | B40: Incluida | D40: =350
A41: 💡 Si marcas Reforma Integral, desmarca Reforma Cocina y Reforma Baño por separado (ya están incluidas). Precios orientativos España 2025: cocina media ~6.000-9.000€ · baño completo ~4.500-5.500€ · integral básica ~500€/m².
A42: 💰 INVERSIÓN TOTAL ESTIMADA (suma componentes seleccionados) | D42: =SUM(D31:D40)
A44: 📊 ANÁLISIS FINANCIERO MENSUAL
...

Sheet 📊 Dashboard
A1: RENTTIA · Dashboard R2R
A2: ='Calculadora R2R'!B7&" · "&'Calculadora R2R'!B6&" — "&TEXT(TODAY(),"DD/MM/YYYY")
A4: 💵 INGRESOS Y COSTES MENSUALES
B5: Ingresos brutos / mes | E5: Alquiler neto al propietario
B6: ='Calculadora R2R'!D26 | E6: ='Calculadora R2R'!B9
A8: 🧾 FISCALIDAD MENSUAL
B9: IVA 21% (solo Explotación) | E9: Gastos suministros totales
B10: ='Calculadora R2R'!B47 | E10: ='Calculadora R2R'!B46
A12: 🏆 MARGEN Y GANANCIA
B13: 🏆 MARGEN NETO MENSUAL REAL | E13: 👤 Ganancia neta / habitación
B14: ='Calculadora R2R'!D51 | E14: ='Calculadora R2R'!D52
A16: 🚪 HABITACIONES Y TIPO DE CONTRATO
B17: Total habitaciones activas | E17: Tipo de contrato
B18: ='Calculadora R2R'!B12 | E18: ='Calculadora R2R'!B7
A20: 💰 INVERSIÓN INICIAL
B21: Inversión en obra y mobiliario | E21: Fianza al propietario (2m)
B22: ='Calculadora R2R'!D42 | E22: ='Calculadora R2R'!B61
B24: 💸 DESEMBOLSO INICIAL TOTAL | E24: 📅 Payback (meses)
B25: ='Calculadora R2R'!B62 | E25: ='Calculadora R2R'!B63
A27: 📊 RENTABILIDAD ANUAL
B28: Ingresos brutos anuales | E28: Beneficio neto anual
B29: ='Calculadora R2R'!B65 | E29: ='Calculadora R2R'!B66
B31: ROI anual (% sobre inversión) | E31: Precio medio hab. activas
B32: ='Calculadora R2R'!B64 | E32: =IFERROR('Calculadora R2R'!D26/'Calculadora R2R'!B12,0)
A35: RENTTIA · renttia.es · Documento orientativo.
